[11/19/2022 11:05:49 PM:pyrogram.dispatcher:253:ERROR] 'id'
Traceback (most recent call last):
  File "/home/roy/.local/lib/python3.8/site-packages/pyrogram/dispatcher.py", line 240, in handler_worker
    await handler.callback(self.client, *args)
  File "/home/roy/AutoAnura/plugins/p_ttishow.py", line 249, in list_users
    out += f"<a href=tg://user?id={user['id']}>{user['name']}</a>"
KeyError: 'id'
